Workbook
Name lg: lg!$A$6:$A$9
Name Teams: 'ef-FT'!$E$4:$E$19
Name TiZo: 'ef-FT'!$BS$3:$BS$38
Name type: lg!$B$14:$B$16

Sheet Fixture
A1: Language | B1: English | D1: Ti-Zo | E1: - 04:00 ET | J1: =HYPERLINK('ef-FT'!$C$37&"g"&HLOOKUP('ef-FT'!E36,'ef-FT'!$E$36:$N$38,2,),PROPER(TEXT('ef-FT'!E36,"mmmm"))) -> Marzo | K1: =HYPERLINK('ef-FT'!$C$37&"g"&HLOOKUP('ef-FT'!F36,'ef-FT'!$E$36:$N$38,2,),PROPER(TEXT('ef-FT'!F36,"mmmm"))) -> Abril | L1: =HYPERLINK('ef-FT'!$C$37&"g"&HLOOKUP('ef-FT'!G36,'ef-FT'!$E$36:$N$38,2,),PROPER(TEXT('ef-FT'!G36,"mmmm"))) -> Mayo | M1: =HYPERLINK('ef-FT'!$C$37&"g"&HLOOKUP('ef-FT'!H36,'ef-FT'!$E$36:$N$38,2,),PROPER(TEXT('ef-FT'!H36,"mmmm"))) -> Junio
J2: =HYPERLINK('ef-FT'!$C$37&"g"&HLOOKUP('ef-FT'!I36,'ef-FT'!$E$36:$N$38,2,),PROPER(TEXT('ef-FT'!I36,"mmmm"))) -> Julio | K2: =HYPERLINK('ef-FT'!$C$37&"g"&HLOOKUP('ef-FT'!J36,'ef-FT'!$E$36:$N$38,2,),PROPER(TEXT('ef-FT'!J36,"mmmm"))) -> Agosto | L2: =HYPERLINK('ef-FT'!$C$37&"g"&HLOOKUP('ef-FT'!K36,'ef-FT'!$E$36:$N$38,2,),PROPER(TEXT('ef-FT'!K36,"mmmm"))) -> Septiembre | M2: =HYPERLINK('ef-FT'!$C$37&"g"&HLOOKUP('ef-FT'!L36,'ef-FT'!$E$36:$N$38,2,),PROPER(TEXT('ef-FT'!L36,"mmmm"))) -> Octubre
B3: =lg!H4 -> Follow | C3: Los Angeles | D3: <- & -> | E3: Dallas
A4: =lg!B4 -> Date | B4: =lg!C4 -> Time | C4: =lg!D4 -> Home | D4: =lg!E4 -> R | E4: =lg!F4 -> Away | F4: =lg!G4 -> R | J4: www.excel-fixtures.com
A5: ='ef-FT'!K44 -> 40262.5 | B5: - | C5: ='ef-FT'!E44 -> Seattle Sounders FC | D5: ='ef-FT'!M44 -> 2 | E5: ='ef-FT'!G44 -> Philadelphia Union | F5: ='ef-FT'!O44 -> 0
A6: ='ef-FT'!K45 -> 40262.5 | B6: - | C6: ='ef-FT'!E45 -> Chivas USA | D6: ='ef-FT'!M45 -> 0 | E6: ='ef-FT'!G45 -> Colorado | F6: ='ef-FT'!O45 -> 1 | J6: "for more Soccer Fixtures of Tournaments around the World"
A7: ='ef-FT'!K46 -> 40264.5 | B7: - | C7: ='ef-FT'!E46 -> Dallas | D7: ='ef-FT'!M46 -> 1 | E7: ='ef-FT'!G46 -> Houston | F7: ='ef-FT'!O46 -> 1
A8: ='ef-FT'!K47 -> 40264.5 | B8: - | C8: ='ef-FT'!E47 -> Columbus | D8: ='ef-FT'!M47 -> 2 | E8: ='ef-FT'!G47 -> Toronto FC | F8: ='ef-FT'!O47 -> 0
A9: ='ef-FT'!K48 -> 40264.5 | B9: - | C9: ='ef-FT'!E48 -> New York Red Bulls | D9: ='ef-FT'!M48 -> 1 | E9: ='ef-FT'!G48 -> Chicago | F9: ='ef-FT'!O48 -> 0
A10: ='ef-FT'!K49 -> 40264.5 | B10: - | C10: ='ef-FT'!E49 -> Kansas City | D10: ='ef-FT'!M49 -> 4 | E10: ='ef-FT'!G49 -> DC United | F10: ='ef-FT'!O49 -> 0
A11: ='ef-FT'!K50 -> 40264.5 | B11: - | C11: ='ef-FT'!E50 -> San Jose | D11: ='ef-FT'!M50 -> 0 | E11: ='ef-FT'!G50 -> Real Salt Lake | F11: ='ef-FT'!O50 -> 3
A12: ='ef-FT'!K51 -> 40264.5 | B12: - | C12: ='ef-FT'!E51 -> Los Angeles | D12: ='ef-FT'!M51 -> 1 | E12: ='ef-FT'!G51 -> New England | F12: ='ef-FT'!O51 -> 0
A13: ='ef-FT'!K52 -> 40269.5 | B13: - | C13: ='ef-FT'!E52 -> Houston | D13: ='ef-FT'!M52 -> 2 | E13: ='ef-FT'!G52 -> Real Salt Lake | F13: ='ef-FT'!O52 -> 1
A14: ='ef-FT'!K53 -> 40269.5 | B14: - | C14: ='ef-FT'!E53 -> Los Angeles | D14: ='ef-FT'!M53 -> 2 | E14: ='ef-FT'!G53 -> Chivas USA | F14: ='ef-FT'!O53 -> 0
A15: ='ef-FT'!K54 -> 40271.5 | B15: - | C15: ='ef-FT'!E54 -> Colorado | D15: ='ef-FT'!M54 -> 2 | E15: ='ef-FT'!G54 -> Chicago | F15: ='ef-FT'!O54 -> 2 | G15: =HYPERLINK('ef-FT'!$C$36,"á") -> á
A16: ='ef-FT'!K55 -> 40271.5 | B16: - | C16: ='ef-FT'!E55 -> DC United | D16: ='ef-FT'!M55 -> 0 | E16: ='ef-FT'!G55 -> New England | F16: ='ef-FT'!O55 -> 2
A17: ='ef-FT'!K56 -> 40271.5 | B17: - | C17: ='ef-FT'!E56 -> Seattle Sounders FC | D17: ='ef-FT'!M56 -> 0 | E17: ='ef-FT'!G56 -> New York Red Bulls | F17: ='ef-FT'!O56 -> 1
A18: ='ef-FT'!K57 -> 40278.5 | B18: - | C18: ='ef-FT'!E57 -> Chivas USA | D18: ='ef-FT'!M57 -> 2 | E18: ='ef-FT'!G57 -> New York Red Bulls | F18: ='ef-FT'!O57 -> 0
A19: ='ef-FT'!K58 -> 40278.5 | B19: - | C19: ='ef-FT'!E58 -> Philadelphia Union | D19: ='ef-FT'!M58 -> 3 | E19: ='ef-FT'!G58 -> DC United | F19: ='ef-FT'!O58 -> 2
A20: ='ef-FT'!K59 -> 40278.5 | B20: - | C20: ='ef-FT'!E59 -> New England | D20: ='ef-FT'!M59 -> 4 | E20: ='ef-FT'!G59 -> Toronto FC | F20: ='ef-FT'!O59 -> 1
A21: ='ef-FT'!K60 -> 40278.5 | B21: - | C21: ='ef-FT'!E60 -> Chicago | D21: ='ef-FT'!M60 -> 1 | E21: ='ef-FT'!G60 -> San Jose | F21: ='ef-FT'!O60 -> 2
A22: ='ef-FT'!K61 -> 40278.5 | B22: - | C22: ='ef-FT'!E61 -> Dallas | D22: ='ef-FT'!M61 -> 2 | E22: ='ef-FT'!G61 -> Columbus | F22: ='ef-FT'!O61 -> 2
A23: ='ef-FT'!K62 -> 40278.5 | B23: - | C23: ='ef-FT'!E62 -> Houston | D23: ='ef-FT'!M62 -> 0 | E23: ='ef-FT'!G62 -> Los Angeles | F23: ='ef-FT'!O62 -> 2
A24: ='ef-FT'!K63 -> 40278.5 | B24: - | C24: ='ef-FT'!E63 -> Kansas City | D24: ='ef-FT'!M63 -> 1 | E24: ='ef-FT'!G63 -> Colorado | F24: ='ef-FT'!O63 -> 0
A25: ='ef-FT'!K64 -> 40278.5 | B25: - | C25: ='ef-FT'!E64 -> Real Salt Lake | D25: ='ef-FT'!M64 -> 2 | E25: ='ef-FT'!G64 -> Seattle Sounders FC | F25: ='ef-FT'!O64 -> 2
A26: ='ef-FT'!K65 -> 40283.5 | B26: - | C26: ='ef-FT'!E65 -> Toronto FC | D26: ='ef-FT'!M65 -> 2 | E26: ='ef-FT'!G65 -> Philadelphia Union | F26: ='ef-FT'!O65 -> 1 | G26: =HYPERLINK('ef-FT'!$C$36,"á") -> á
A27: ='ef-FT'!K66 -> 40285.5 | B27: - | C27: ='ef-FT'!E66 -> Los Angeles | D27: ='ef-FT'!M66 -> 2 | E27: ='ef-FT'!G66 -> Real Salt Lake | F27: ='ef-FT'!O66 -> 1
A28: ='ef-FT'!K67 -> 40285.5 | B28: - | C28: ='ef-FT'!E67 -> Seattle Sounders FC | D28: ='ef-FT'!M67 -> 1 | E28: ='ef-FT'!G67 -> Kansas City | F28: ='ef-FT'!O67 -> 0
A29: ='ef-FT'!K68 -> 40285.5 | B29: - | C29: ='ef-FT'!E68 -> Houston | D29: ='ef-FT'!M68 -> 3 | E29: ='ef-FT'!G68 -> Chivas USA | F29: ='ef-FT'!O68 -> 0
A30: ='ef-FT'!K69 -> 40285.5 | B30: - | C30: ='ef-FT'!E69 -> DC United | D30: ='ef-FT'!M69 -> 0 | E30: ='ef-FT'!G69 -> Chicago | F30: ='ef-FT'!O69 -> 2
A31: ='ef-FT'!K70 -> 40285.5 | B31: - | C31: ='ef-FT'!E70 -> New York Red Bulls | D31: ='ef-FT'!M70 -> 2 | E31: ='ef-FT'!G70 -> Dallas | F31: ='ef-FT'!O70 -> 1
A32: ='ef-FT'!K71 -> 40285.5 | B32: - | C32: ='ef-FT'!E71 -> San Jose | D32: ='ef-FT'!M71 -> 2 | E32: ='ef-FT'!G71 -> New England | F32: ='ef-FT'!O71 -> 0
A33: ='ef-FT'!K72 -> 40286.5 | B33: - | C33: ='ef-FT'!E72 -> Colorado | D33: ='ef-FT'!M72 -> 3 | E33: ='ef-FT'!G72 -> Toronto FC | F33: ='ef-FT'!O72 -> 1
A34: ='ef-FT'!K73 -> 40290.5 | B34: - | C34: ='ef-FT'!E73 -> Dallas | D34: ='ef-FT'!M73 -> 2 | E34: ='ef-FT'!G73 -> Seattle Sounders FC | F34: ='ef-FT'!O73 -> 2
A35: ='ef-FT'!K74 -> 40292.5 | B35: - | C35: ='ef-FT'!E74 -> New York Red Bulls | D35: ='ef-FT'!M74 -> 2 | E35: ='ef-FT'!G74 -> Philadelphia Union | F35: ='ef-FT'!O74 -> 1
A36: ='ef-FT'!K75 -> 40292.5 | B36: - | C36: ='ef-FT'!E75 -> Columbus | D36: ='ef-FT'!M75 -> 1 | E36: ='ef-FT'!G75 -> Real Salt Lake | F36: ='ef-FT'!O75 -> 0
A37: ='ef-FT'!K76 -> 40292.5 | B37: - | C37: ='ef-FT'!E76 -> New England | D37: ='ef-FT'!M76 -> 1 | E37: ='ef-FT'!G76 -> Colorado | F37: ='ef-FT'!O76 -> 2 | G37: =HYPERLINK('ef-FT'!$C$36,"á") -> á | J37: www.excel-fixtures.com
A38: ='ef-FT'!K77 -> 40292.5 | B38: - | C38: ='ef-FT'!E77 -> Chicago | D38: ='ef-FT'!M77 -> 2 | E38: ='ef-FT'!G77 -> Houston | F38: ='ef-FT'!O77 -> 0
A39: ='ef-FT'!K78 -> 40292.5 | B39: - | C39: ='ef-FT'!E78 -> Kansas City | D39: ='ef-FT'!M78 -> 0 | E39: ='ef-FT'!G78 -> Los Angeles | F39: ='ef-FT'!O78 -> 0 | J39: "for more Soccer Fixtures of Tournaments around the World"
A40: ='ef-FT'!K79 -> 40292.5 | B40: - | C40: ='ef-FT'!E79 -> Chivas USA | D40: ='ef-FT'!M79 -> 3 | E40: ='ef-FT'!G79 -> San Jose | F40: ='ef-FT'!O79 -> 2
...

Sheet Table
C1: Eastern Conference
C2: Overall | J2: Home | Q2: Away
A3: ='ef-FT'!D3 -> # | B3: =lg!L4 -> Team | C3: =lg!M4 -> P | D3: =lg!N4 -> W | E3: =lg!O4 -> D | F3: =lg!P4 -> L | G3: =lg!Q4 -> Pts | H3: =lg!R4 -> GF - GC | I3: =lg!S4 -> GD | J3: =lg!M4 -> P | K3: =lg!N4 -> W | L3: =lg!O4 -> D | M3: =lg!P4 -> L | N3: =lg!Q4 -> Pts | O3: =lg!R4 -> GF - GC | P3: =lg!S4 -> GD | Q3: =lg!M4 -> P | R3: =lg!N4 -> W | S3: =lg!O4 -> D | T3: =lg!P4 -> L | U3: =lg!Q4 -> Pts | V3: =lg!R4 -> GF - GC | W3: =lg!S4 -> GD
A4: 1 | B4: ='ef-FT'!AU4 -> Columbus | C4: ='ef-FT'!AV4 -> 20 | D4: ='ef-FT'!AW4 -> 11 | E4: ='ef-FT'!AX4 -> 4 | F4: ='ef-FT'!AY4 -> 5 | G4: ='ef-FT'!AZ4 -> 37 | H4: ='ef-FT'!BA4 -> 28 - 19 | I4: ='ef-FT'!BB4 -> 9 | ... W4: ='ef-FT'!BP4 -> -1
A5: 2 | B5: ='ef-FT'!AU5 -> New York Red Bulls | C5: ='ef-FT'!AV5 -> 20 | D5: ='ef-FT'!AW5 -> 9 | E5: ='ef-FT'!AX5 -> 4 | F5: ='ef-FT'!AY5 -> 7 | G5: ='ef-FT'!AZ5 -> 31 | H5: ='ef-FT'!BA5 -> 21 - 22 | I5: ='ef-FT'!BB5 -> -1 | ... W5: ='ef-FT'!BP5 -> -3
A6: 3 | B6: ='ef-FT'!AU6 -> Toronto FC | C6: ='ef-FT'!AV6 -> 19 | D6: ='ef-FT'!AW6 -> 7 | E6: ='ef-FT'!AX6 -> 5 | F6: ='ef-FT'!AY6 -> 7 | G6: ='ef-FT'!AZ6 -> 26 | H6: ='ef-FT'!BA6 -> 21 - 21 | I6: ='ef-FT'!BB6 -> 0 | ... W6: ='ef-FT'!BP6 -> -9
A7: 4 | B7: ='ef-FT'!AU7 -> Chicago | C7: ='ef-FT'!AV7 -> 16 | D7: ='ef-FT'!AW7 -> 5 | E7: ='ef-FT'!AX7 -> 6 | F7: ='ef-FT'!AY7 -> 5 | G7: ='ef-FT'!AZ7 -> 21 | H7: ='ef-FT'!BA7 -> 21 - 21 | I7: ='ef-FT'!BB7 -> 0 | ... W7: ='ef-FT'!BP7 -> -1
A8: 5 | B8: ='ef-FT'!AU8 -> New England | C8: ='ef-FT'!AV8 -> 18 | D8: ='ef-FT'!AW8 -> 6 | E8: ='ef-FT'!AX8 -> 3 | F8: ='ef-FT'!AY8 -> 9 | G8: ='ef-FT'!AZ8 -> 21 | H8: ='ef-FT'!BA8 -> 18 - 27 | I8: ='ef-FT'!BB8 -> -9 | ... W8: ='ef-FT'!BP8 -> -11
A9: 6 | B9: ='ef-FT'!AU9 -> Kansas City | C9: ='ef-FT'!AV9 -> 19 | D9: ='ef-FT'!AW9 -> 5 | E9: ='ef-FT'!AX9 -> 5 | F9: ='ef-FT'!AY9 -> 9 | G9: ='ef-FT'!AZ9 -> 20 | H9: ='ef-FT'!BA9 -> 15 - 22 | I9: ='ef-FT'!BB9 -> -7 | ... W9: ='ef-FT'!BP9 -> -9
A10: 7 | B10: ='ef-FT'!AU10 -> Philadelphia Union | C10: ='ef-FT'!AV10 -> 19 | D10: ='ef-FT'!AW10 -> 4 | E10: ='ef-FT'!AX10 -> 5 | F10: ='ef-FT'!AY10 -> 10 | G10: ='ef-FT'!AZ10 -> 17 | H10: ='ef-FT'!BA10 -> 23 - 33 | I10: ='ef-FT'!BB10 -> -10 | ... W10: ='ef-FT'!BP10 -> -12
A11: 8 | B11: ='ef-FT'!AU11 -> DC United | C11: ='ef-FT'!AV11 -> 20 | D11: ='ef-FT'!AW11 -> 3 | E11: ='ef-FT'!AX11 -> 3 | F11: ='ef-FT'!AY11 -> 14 | G11: ='ef-FT'!AZ11 -> 12 | H11: ='ef-FT'!BA11 -> 13 - 35 | I11: ='ef-FT'!BB11 -> -22 | ... W11: ='ef-FT'!BP11 -> -13
C13: Western Conference
C14: Overall | J14: Home | Q14: Away
A15: =A3 -> # | B15: =B3 -> Team | C15: =C3 -> P | D15: =D3 -> W | E15: =E3 -> D | F15: =F3 -> L | G15: =G3 -> Pts | H15: =H3 -> GF - GC | ... W15: =W3 -> GD
A16: 9 | B16: ='ef-FT'!AU12 -> Los Angeles | C16: ='ef-FT'!AV12 -> 20 | D16: ='ef-FT'!AW12 -> 13 | E16: ='ef-FT'!AX12 -> 4 | F16: ='ef-FT'!AY12 -> 3 | G16: ='ef-FT'!AZ12 -> 43 | H16: ='ef-FT'!BA12 -> 32 - 13 | I16: ='ef-FT'!BB12 -> 19 | ... W16: ='ef-FT'!BP12 -> 9
A17: 10 | B17: ='ef-FT'!AU13 -> Real Salt Lake | C17: ='ef-FT'!AV13 -> 21 | D17: ='ef-FT'!AW13 -> 11 | E17: ='ef-FT'!AX13 -> 6 | F17: ='ef-FT'!AY13 -> 4 | G17: ='ef-FT'!AZ13 -> 39 | H17: ='ef-FT'!BA13 -> 36 - 16 | I17: ='ef-FT'!BB13 -> 20 | ... W17: ='ef-FT'!BP13 -> 0
A18: 11 | B18: ='ef-FT'!AU14 -> Dallas | C18: ='ef-FT'!AV14 -> 19 | D18: ='ef-FT'!AW14 -> 8 | E18: ='ef-FT'!AX14 -> 9 | F18: ='ef-FT'!AY14 -> 2 | G18: ='ef-FT'!AZ14 -> 33 | H18: ='ef-FT'!BA14 -> 27 - 17 | I18: ='ef-FT'!BB14 -> 10 | ... W18: ='ef-FT'!BP14 -> 3
A19: 12 | B19: ='ef-FT'!AU15 -> Seattle Sounders FC | C19: ='ef-FT'!AV15 -> 21 | D19: ='ef-FT'!AW15 -> 8 | E19: ='ef-FT'!AX15 -> 5 | F19: ='ef-FT'!AY15 -> 8 | G19: ='ef-FT'!AZ15 -> 29 | H19: ='ef-FT'!BA15 -> 23 - 25 | I19: ='ef-FT'!BB15 -> -2 | ... W19: ='ef-FT'!BP15 -> -4
A20: 13 | B20: ='ef-FT'!AU16 -> Colorado | C20: ='ef-FT'!AV16 -> 19 | D20: ='ef-FT'!AW16 -> 7 | E20: ='ef-FT'!AX16 -> 7 | F20: ='ef-FT'!AY16 -> 5 | G20: ='ef-FT'!AZ16 -> 28 | H20: ='ef-FT'!BA16 -> 21 - 18 | I20: ='ef-FT'!BB16 -> 3 | ... W20: ='ef-FT'!BP16 -> -1
A21: 14 | B21: ='ef-FT'!AU17 -> San Jose | C21: ='ef-FT'!AV17 -> 18 | D21: ='ef-FT'!AW17 -> 7 | E21: ='ef-FT'!AX17 -> 5 | F21: ='ef-FT'!AY17 -> 6 | G21: ='ef-FT'!AZ17 -> 26 | H21: ='ef-FT'!BA17 -> 21 - 20 | I21: ='ef-FT'!BB17 -> 1 | ... W21: ='ef-FT'!BP17 -> -1
A22: 15 | B22: ='ef-FT'!AU18 -> Houston | C22: ='ef-FT'!AV18 -> 20 | D22: ='ef-FT'!AW18 -> 5 | E22: ='ef-FT'!AX18 -> 5 | F22: ='ef-FT'!AY18 -> 10 | G22: ='ef-FT'!AZ18 -> 20 | H22: ='ef-FT'!BA18 -> 22 - 30 | I22: ='ef-FT'!BB18 -> -8 | ... W22: ='ef-FT'!BP18 -> -12
A23: 16 | B23: ='ef-FT'!AU19 -> Chivas USA | C23: ='ef-FT'!AV19 -> 19 | D23: ='ef-FT'!AW19 -> 5 | E23: ='ef-FT'!AX19 -> 4 | F23: ='ef-FT'!AY19 -> 10 | G23: ='ef-FT'!AZ19 -> 19 | H23: ='ef-FT'!BA19 -> 22 - 25 | I23: ='ef-FT'!BB19 -> -3 | ... W23: ='ef-FT'!BP19 -> -3
C25: www.excel-fixtures.com | J25: www.excel-fixtures.com | Q25: www.excel-fixtures.com
C28: "for more Soccer Fixtures of Tournaments around the World" | J28: "for more Soccer Fixtures of Tournaments around the World" | Q28: "for more Soccer Fixtures of Tournaments around the World"

Sheet ef-LeagueStats
B1: =lg!U4 -> type | D1: Overall
B2: =lg!H4 -> Follow | D2: =Fixture!C3 -> Los Angeles | E2: <- change in Fixture Sheet -> | H2: =Fixture!E3 -> Dallas
B4: =lg!V4 -> Most Points | D4: =lg!W4 -> Most Wins | F4: =lg!X4 -> Fewest Losses | H4: =lg!Y4 -> Most Goal Scored
A5: 1 | B5: ='ef-FT'!GR4 -> Los Angeles | C5: ='ef-FT'!HV4 -> 43 | D5: ='ef-FT'!GT4 -> Los Angeles | E5: ='ef-FT'!HX4 -> 13 | F5: ='ef-FT'!GW4 -> Dallas | G5: ='ef-FT'!IA4 -> 2 | H5: ='ef-FT'!GX4 -> Real Salt Lake | I5: ='ef-FT'!IB4 -> 36
A6: 2 | B6: ='ef-FT'!GR5 -> Real Salt Lake | C6: ='ef-FT'!HV5 -> 39 | D6: ='ef-FT'!GT5 -> Columbus | E6: ='ef-FT'!HX5 -> 11 | F6: ='ef-FT'!GW5 -> Los Angeles | G6: ='ef-FT'!IA5 -> 3 | H6: ='ef-FT'!GX5 -> Los Angeles | I6: ='ef-FT'!IB5 -> 32
A7: 3 | B7: ='ef-FT'!GR6 -> Columbus | C7: ='ef-FT'!HV6 -> 37 | D7: ='ef-FT'!GT6 -> Real Salt Lake | E7: ='ef-FT'!HX6 -> 11 | F7: ='ef-FT'!GW6 -> Real Salt Lake | G7: ='ef-FT'!IA6 -> 4 | H7: ='ef-FT'!GX6 -> Columbus | I7: ='ef-FT'!IB6 -> 28
A8: 4 | B8: ='ef-FT'!GR7 -> Dallas | C8: ='ef-FT'!HV7 -> 33 | D8: ='ef-FT'!GT7 -> New York Red Bulls | E8: ='ef-FT'!HX7 -> 9 | F8: ='ef-FT'!GW7 -> Columbus | G8: ='ef-FT'!IA7 -> 5 | H8: ='ef-FT'!GX7 -> Dallas | I8: ='ef-FT'!IB7 -> 27
A9: 5 | B9: ='ef-FT'!GR8 -> New York Red Bulls | C9: ='ef-FT'!HV8 -> 31 | D9: ='ef-FT'!GT8 -> Dallas | E9: ='ef-FT'!HX8 -> 8 | F9: ='ef-FT'!GW8 -> Chicago | G9: ='ef-FT'!IA8 -> 5 | H9: ='ef-FT'!GX8 -> Philadelphia Union | I9: ='ef-FT'!IB8 -> 23
A10: 6 | B10: ='ef-FT'!GR9 -> Seattle Sounders FC | C10: ='ef-FT'!HV9 -> 29 | D10: ='ef-FT'!GT9 -> Seattle Sounders FC | E10: ='ef-FT'!HX9 -> 8 | F10: ='ef-FT'!GW9 -> Colorado | G10: ='ef-FT'!IA9 -> 5 | H10: ='ef-FT'!GX9 -> Seattle Sounders FC | I10: ='ef-FT'!IB9 -> 23
A11: 7 | B11: ='ef-FT'!GR10 -> Colorado | C11: ='ef-FT'!HV10 -> 28 | D11: ='ef-FT'!GT10 -> Toronto FC | E11: ='ef-FT'!HX10 -> 7 | F11: ='ef-FT'!GW10 -> San Jose | G11: ='ef-FT'!IA10 -> 6 | H11: ='ef-FT'!GX10 -> Houston | I11: ='ef-FT'!IB10 -> 22
A12: 8 | B12: ='ef-FT'!GR11 -> Toronto FC | C12: ='ef-FT'!HV11 -> 26 | D12: ='ef-FT'!GT11 -> Colorado | E12: ='ef-FT'!HX11 -> 7 | F12: ='ef-FT'!GW11 -> New York Red Bulls | G12: ='ef-FT'!IA11 -> 7 | H12: ='ef-FT'!GX11 -> Chivas USA | I12: ='ef-FT'!IB11 -> 22
A13: 9 | B13: ='ef-FT'!GR12 -> San Jose | C13: ='ef-FT'!HV12 -> 26 | D13: ='ef-FT'!GT12 -> San Jose | E13: ='ef-FT'!HX12 -> 7 | F13: ='ef-FT'!GW12 -> Toronto FC | G13: ='ef-FT'!IA12 -> 7 | H13: ='ef-FT'!GX12 -> New York Red Bulls | I13: ='ef-FT'!IB12 -> 21
A14: 10 | B14: ='ef-FT'!GR13 -> New England | C14: ='ef-FT'!HV13 -> 21 | D14: ='ef-FT'!GT13 -> New England | E14: ='ef-FT'!HX13 -> 6 | F14: ='ef-FT'!GW13 -> Seattle Sounders FC | G14: ='ef-FT'!IA13 -> 8 | H14: ='ef-FT'!GX13 -> Toronto FC | I14: ='ef-FT'!IB13 -> 21
A15: 11 | B15: ='ef-FT'!GR14 -> Chicago | C15: ='ef-FT'!HV14 -> 21 | D15: ='ef-FT'!GT14 -> Chicago | E15: ='ef-FT'!HX14 -> 5 | F15: ='ef-FT'!GW14 -> New England | G15: ='ef-FT'!IA14 -> 9 | H15: ='ef-FT'!GX14 -> Chicago | I15: ='ef-FT'!IB14 -> 21
A16: 12 | B16: ='ef-FT'!GR15 -> Kansas City | C16: ='ef-FT'!HV15 -> 20 | D16: ='ef-FT'!GT15 -> Kansas City | E16: ='ef-FT'!HX15 -> 5 | F16: ='ef-FT'!GW15 -> Kansas City | G16: ='ef-FT'!IA15 -> 9 | H16: ='ef-FT'!GX15 -> Colorado | I16: ='ef-FT'!IB15 -> 21
... A20: 16 | B20: ='ef-FT'!GR19 -> DC United | C20: ='ef-FT'!HV19 -> 12 | D20: ='ef-FT'!GT19 -> DC United | E20: ='ef-FT'!HX19 -> 3 | F20: ='ef-FT'!GW19 -> DC United | G20: ='ef-FT'!IA19 -> 14 | H20: ='ef-FT'!GX19 -> DC United | I20: ='ef-FT'!IB19 -> 13
B22: www.excel-fixtures.com | D22: www.excel-fixtures.com | F22: www.excel-fixtures.com | H22: www.excel-fixtures.com
B24: =lg!Z4 -> Fewest Goals Conceded | D24: =lg!AA4 -> Highest Goal Difference | F24: =lg!AB4 -> Fewest Games Failed to Score | H24: =lg!AC4 -> Most Clean Sheets
A25: 1 | B25: ='ef-FT'!HA4 -> Los Angeles | C25: ='ef-FT'!IE4 -> 13 | D25: ='ef-FT'!HB4 -> Real Salt Lake | E25: ='ef-FT'!IF4 -> 20 | F25: ='ef-FT'!HE4 -> Dallas | G25: ='ef-FT'!II4 -> 1 | H25: ='ef-FT'!HF4 -> Los Angeles | I25: ='ef-FT'!IJ4 -> 11
A26: 2 | B26: ='ef-FT'!HA5 -> Real Salt Lake | C26: ='ef-FT'!IE5 -> 16 | D26: ='ef-FT'!HB5 -> Los Angeles | E26: ='ef-FT'!IF5 -> 19 | F26: ='ef-FT'!HE5 -> Chicago | G26: ='ef-FT'!II5 -> 3 | H26: ='ef-FT'!HF5 -> Real Salt Lake | I26: ='ef-FT'!IJ5 -> 9
A27: 3 | B27: ='ef-FT'!HA6 -> Dallas | C27: ='ef-FT'!IE6 -> 17 | D27: ='ef-FT'!HB6 -> Dallas | E27: ='ef-FT'!IF6 -> 10 | F27: ='ef-FT'!HE6 -> Philadelphia Union | G27: ='ef-FT'!II6 -> 3 | H27: ='ef-FT'!HF6 -> Columbus | I27: ='ef-FT'!IJ6 -> 8
A28: 4 | B28: ='ef-FT'!HA7 -> Colorado | C28: ='ef-FT'!IE7 -> 18 | D28: ='ef-FT'!HB7 -> Columbus | E28: ='ef-FT'!IF7 -> 9 | F28: ='ef-FT'!HE7 -> Real Salt Lake | G28: ='ef-FT'!II7 -> 4 | H28: ='ef-FT'!HF7 -> New York Red Bulls | I28: ='ef-FT'!IJ7 -> 8
A29: 5 | B29: ='ef-FT'!HA8 -> Columbus | C29: ='ef-FT'!IE8 -> 19 | D29: ='ef-FT'!HB8 -> Colorado | E29: ='ef-FT'!IF8 -> 3 | F29: ='ef-FT'!HE8 -> Colorado | G29: ='ef-FT'!II8 -> 4 | H29: ='ef-FT'!HF8 -> Seattle Sounders FC | I29: ='ef-FT'!IJ8 -> 8
A30: 6 | B30: ='ef-FT'!HA9 -> San Jose | C30: ='ef-FT'!IE9 -> 20 | D30: ='ef-FT'!HB9 -> San Jose | E30: ='ef-FT'!IF9 -> 1 | F30: ='ef-FT'!HE9 -> Columbus | G30: ='ef-FT'!II9 -> 5 | H30: ='ef-FT'!HF9 -> Kansas City | I30: ='ef-FT'!IJ9 -> 7
A31: 7 | B31: ='ef-FT'!HA10 -> Toronto FC | C31: ='ef-FT'!IE10 -> 21 | D31: ='ef-FT'!HB10 -> Toronto FC | E31: ='ef-FT'!IF10 -> 0 | F31: ='ef-FT'!HE10 -> Los Angeles | G31: ='ef-FT'!II10 -> 5 | H31: ='ef-FT'!HF10 -> San Jose | I31: ='ef-FT'!IJ10 -> 7
A32: 8 | B32: ='ef-FT'!HA11 -> Chicago | C32: ='ef-FT'!IE11 -> 21 | D32: ='ef-FT'!HB11 -> Chicago | E32: ='ef-FT'!IF11 -> 0 | F32: ='ef-FT'!HE11 -> Toronto FC | G32: ='ef-FT'!II11 -> 6 | H32: ='ef-FT'!HF11 -> Toronto FC | I32: ='ef-FT'!IJ11 -> 6
A33: 9 | B33: ='ef-FT'!HA12 -> New York Red Bulls | C33: ='ef-FT'!IE12 -> 22 | D33: ='ef-FT'!HB12 -> New York Red Bulls | E33: ='ef-FT'!IF12 -> -1 | F33: ='ef-FT'!HE12 -> Seattle Sounders FC | G33: ='ef-FT'!II12 -> 6 | H33: ='ef-FT'!HF12 -> New England | I33: ='ef-FT'!IJ12 -> 5
A34: 10 | B34: ='ef-FT'!HA13 -> Kansas City | C34: ='ef-FT'!IE13 -> 22 | D34: ='ef-FT'!HB13 -> Seattle Sounders FC | E34: ='ef-FT'!IF13 -> -2 | F34: ='ef-FT'!HE13 -> San Jose | G34: ='ef-FT'!II13 -> 6 | H34: ='ef-FT'!HF13 -> Dallas | I34: ='ef-FT'!IJ13 -> 5
A35: 11 | B35: ='ef-FT'!HA14 -> Seattle Sounders FC | C35: ='ef-FT'!IE14 -> 25 | D35: ='ef-FT'!HB14 -> Chivas USA | E35: ='ef-FT'!IF14 -> -3 | F35: ='ef-FT'!HE14 -> New York Red Bulls | G35: ='ef-FT'!II14 -> 7 | H35: ='ef-FT'!HF14 -> Colorado | I35: ='ef-FT'!IJ14 -> 5
A36: 12 | B36: ='ef-FT'!HA15 -> Chivas USA | C36: ='ef-FT'!IE15 -> 25 | D36: ='ef-FT'!HB15 -> Kansas City | E36: ='ef-FT'!IF15 -> -7 | F36: ='ef-FT'!HE15 -> Houston | G36: ='ef-FT'!II15 -> 7 | H36: ='ef-FT'!HF15 -> Houston | I36: ='ef-FT'!IJ15 -> 5
... A40: 16 | B40: ='ef-FT'!HA19 -> DC United | C40: ='ef-FT'!IE19 -> 35 | D40: ='ef-FT'!HB19 -> DC United | E40: ='ef-FT'!IF19 -> -22 | F40: ='ef-FT'!HE19 -> DC United | G40: ='ef-FT'!II19 -> 13 | H40: ='ef-FT'!HF19 -> Philadelphia Union | I40: ='ef-FT'!IJ19 -> 0
A45: 1
A46: 2
A47: 3
A48: 4
A49: 5
A50: 6
A51: 7
A52: 8
A53: 9
...

Sheet ef-TeamStats
A1: =lg!U4 -> type | B1: Overall
A2: =lg!H4 -> Follow | B2: =Fixture!C3 -> Los Angeles | F2: <- change in Fixture Sheet -> | G2: =Fixture!E3 -> Dallas
B3: No | C3: Total | D3: =lg!AD4 -> Ave. | E3: Pos | G3: No | H3: Total | I3: =D3 -> Ave. | J3: Pos
A4: Points | B4: ='ef-FT'!IP30 -> 43 | C4: ='ef-FT'!IQ30 -> 20 | D4: ='ef-FT'!IR30 -> 2.15 | E4: ='ef-FT'!IS30 -> 1 | G4: ='ef-FT'!IV30 -> 33 | H4: ='ef-FT'!IW30 -> 19 | I4: ='ef-FT'!IX30 -> 1.7368421 | J4: ='ef-FT'!IY30 -> 4
A6: Goals Scored | B6: ='ef-FT'!IP33 -> 32 | C6: ='ef-FT'!IQ33 -> 20 | D6: ='ef-FT'!IR33 -> 1.6 | E6: ='ef-FT'!IS33 -> 2 | G6: ='ef-FT'!IV33 -> 27 | H6: ='ef-FT'!IW33 -> 19 | I6: ='ef-FT'!IX33 -> 1.4210526 | J6: ='ef-FT'!IY33 -> 4
A8: Goals Conceded | B8: ='ef-FT'!IP34 -> 13 | C8: ='ef-FT'!IQ34 -> 20 | D8: ='ef-FT'!IR34 -> 0.65 | E8: ='ef-FT'!IS34 -> 16 | G8: ='ef-FT'!IV34 -> 17 | H8: ='ef-FT'!IW34 -> 19 | I8: ='ef-FT'!IX34 -> 0.89473684 | J8: ='ef-FT'!IY34 -> 14
A10: Goal Diference | B10: ='ef-FT'!IP35 -> 19 | C10: ='ef-FT'!IQ35 -> 20 | D10: ='ef-FT'!IR35 -> 0.95 | E10: ='ef-FT'!IS35 -> 2 | G10: ='ef-FT'!IV35 -> 10 | H10: ='ef-FT'!IW35 -> 19 | I10: ='ef-FT'!IX35 -> 0.52631579 | J10: ='ef-FT'!IY35 -> 3
B12: No | C12: Total | D12: % | E12: Pos | G12: No | H12: Total | I12: % | J12: Pos
A13: Most Wins | B13: ='ef-FT'!IP31 -> 13 | C13: ='ef-FT'!IQ31 -> 20 | D13: ='ef-FT'!IR31 -> 0.65 | E13: ='ef-FT'!IS31 -> 1 | G13: ='ef-FT'!IV31 -> 8 | H13: ='ef-FT'!IW31 -> 19 | I13: ='ef-FT'!IX31 -> 0.42105263 | J13: ='ef-FT'!IY31 -> 5
A15: Fewest Losses | B15: ='ef-FT'!IP32 -> 3 | C15: ='ef-FT'!IQ32 -> 20 | D15: ='ef-FT'!IR32 -> 0.15 | E15: ='ef-FT'!IS32 -> 2 | G15: ='ef-FT'!IV32 -> 2 | H15: ='ef-FT'!IW32 -> 19 | I15: ='ef-FT'!IX32 -> 0.10526316 | J15: ='ef-FT'!IY32 -> 16
A17: Fewest Games Failed to Score | B17: ='ef-FT'!IP36 -> 5 | C17: ='ef-FT'!IQ36 -> 20 | D17: ='ef-FT'!IR36 -> 0.25 | E17: ='ef-FT'!IS36 -> 7 | G17: ='ef-FT'!IV36 -> 1 | H17: ='ef-FT'!IW36 -> 19 | I17: ='ef-FT'!IX36 -> 0.052631579 | J17: ='ef-FT'!IY36 -> 16
A19: Most Clean Sheets | B19: ='ef-FT'!IP37 -> 11 | C19: ='ef-FT'!IQ37 -> 20 | D19: ='ef-FT'!IR37 -> 0.55 | E19: ='ef-FT'!IS37 -> 1 | G19: ='ef-FT'!IV37 -> 5 | H19: ='ef-FT'!IW37 -> 19 | I19: ='ef-FT'!IX37 -> 0.26315789 | J19: ='ef-FT'!IY37 -> 10
B21: www.excel-fixtures.com | G21: www.excel-fixtures.com
B23: "for more Soccer Fixtures of Tournaments around the World" | G23: "for more Soccer Fixtures of Tournaments around the World"

Sheet HistoriChart
A1: Historic Chart | B1: =lg!H4&" "&lg!L4&"s &" -> Follow Teams & | H1: Columbus | S1: & | T1: Toronto FC | AE1: & | AF1: New England | AX1: =Fixture!C3 -> Los Angeles | AY1: =Fixture!E3 -> Dallas
B2: Eastern Conference
B3: - | C3: - | D3: 1 | E3: 2 | F3: 3 | G3: 4 | H3: 5 | I3: 6 | J3: 7 | K3: 8 | L3: 9 | M3: 10 | N3: 11 | O3: 12 | P3: 13 | Q3: 14 | R3: 15 | S3: 16 | T3: 17 | U3: 18 | V3: 19 | W3: 20 | X3: 21 | Y3: 22 | Z3: 23 | AA3: 24 | AB3: 25 | AC3: 26 | AD3: 27 | AE3: 28 | AF3: 29 | AG3: 30
A4: ='ef-FT'!E4 -> Columbus | B4: 1 | N4: 1 | X4: 1 | AH4: 1
A6: ='ef-FT'!E5 -> New York Red Bulls | B6: 2 | N6: 2 | X6: 2 | AH6: 2
A8: ='ef-FT'!E6 -> Toronto FC | B8: 3 | N8: 3 | X8: 3 | AH8: 3
A10: ='ef-FT'!E7 -> New England | B10: 4 | N10: 4 | X10: 4 | AH10: 4
A12: ='ef-FT'!E8 -> Chicago | B12: 5 | N12: 5 | X12: 5 | AH12: 5
A14: ='ef-FT'!E9 -> Kansas City | B14: 6 | N14: 6 | X14: 6 | AH14: 6
A16: ='ef-FT'!E10 -> Philadelphia Union | B16: 7 | N16: 7 | X16: 7 | AH16: 7
A18: ='ef-FT'!E11 -> DC United | B18: 8 | N18: 8 | X18: 8 | AH18: 8
B22: Western Conference
B23: - | C23: - | D23: 1 | E23: 2 | F23: 3 | G23: 4 | H23: 5 | I23: 6 | J23: 7 | K23: 8 | L23: 9 | M23: 10 | N23: 11 | O23: 12 | P23: 13 | Q23: 14 | R23: 15 | S23: 16 | T23: 17 | U23: 18 | V23: 19 | W23: 20 | X23: 21 | Y23: 22 | Z23: 23 | AA23: 24 | AB23: 25 | AC23: 26 | AD23: 27 | AE23: 28 | AF23: 29 | AG23: 30
A24: ='ef-FT'!E12 -> Los Angeles | B24: 1 | N24: 1 | X24: 1 | AH24: 1
A26: ='ef-FT'!E13 -> Real Salt Lake | B26: 2 | N26: 2 | X26: 2 | AH26: 2
A28: ='ef-FT'!E14 -> Dallas | B28: 3 | N28: 3 | X28: 3 | AH28: 3
A30: ='ef-FT'!E15 -> Seattle Sounders FC | B30: 4 | N30: 4 | X30: 4 | AH30: 4
A32: ='ef-FT'!E16 -> Colorado | B32: 5 | N32: 5 | X32: 5 | AH32: 5
A34: ='ef-FT'!E17 -> San Jose | B34: 6 | N34: 6 | X34: 6 | AH34: 6
A36: ='ef-FT'!E18 -> Houston | B36: 7 | N36: 7 | X36: 7 | AH36: 7
A38: ='ef-FT'!E19 -> Chivas USA | B38: 8 | N38: 8 | X38: 8 | AH38: 8
B41: www.excel-fixtures.com | AC41: www.excel-fixtures.com
B43: "for more Soccer Fixtures of Tournaments around the World" | AC43: "for more Soccer Fixtures of Tournaments around the World"

Sheet ef-FT
YA1: x
F2: General | R2: Home | AD2: Away | BS2: TiZo | BU2: 0.16666667 | CA2: General - General - General - General | CR2: Home - Home - Home - Home | DI2: Away - Away - Away - Away | EB2: General - General - General - General | ES2: Home - Home - Home - Home | FJ2: Away - Away - Away - Away | GA2: Choose pos - Choose pos - Choose pos - Choosepos | GR2: Choose team - Choose team - Choose team - Choose | HI2: 1 | HJ2: 2 | HK2: 3 | HL2: 4 | HM2: 5 | HN2: 6 | HO2: 7 | HP2: 8 | HQ2: 9 | HR2: 10 | HS2: 11 | HT2: 12 | HV2: Choose - Choose - Choose - Choose | JB2: Choose pos 2 - Choose pos 2 - Choose pos 2 - Choose pos2 | JS2: Choose team 2 - Choose team 2 - Choose team 2 - Choose team 2 | KO2: 1 | KV2: =KO2+1 -> 2 | LC2: =KV2+1 -> 3 | LJ2: =LC2+1 -> 4 | LQ2: =LJ2+1 -> 5 | LX2: =LQ2+1 -> 6 | ME2: =LX2+1 -> 7 | ML2: =ME2+1 -> 8 | MS2: =ML2+1 -> 9 | MZ2: =MS2+1 -> 10 | NG2: =MZ2+1 -> 11 | NN2: =NG2+1 -> 12 | NU2: =NN2+1 -> 13 | OB2: =NU2+1 -> 14 | OI2: =OB2+1 -> 15 | OP2: =OI2+1 -> 16 | OW2: =OP2+1 -> 17 | PD2: =OW2+1 -> 18 | PK2: =PD2+1 -> 19 | PR2: =PK2+1 -> 20 | PY2: =PR2+1 -> 21 | QF2: =PY2+1 -> 22 | QM2: =QF2+1 -> 23 | QT2: =QM2+1 -> 24 | RA2: =QT2+1 -> 25 | RH2: =RA2+1 -> 26 | RO2: =RH2+1 -> 27 | RV2: =RO2+1 -> 28 | SC2: =RV2+1 -> 29 | SJ2: =SC2+1 -> 30 | SQ2: =SJ2+1 -> 31 | SX2: =SQ2+1 -> 32 | TE2: =SX2+1 -> 33 | TL2: =TE2+1 -> 34 | TS2: =TL2+1 -> 35 | TZ2: =TS2+1 -> 36 | UG2: =TZ2+1 -> 37 | UN2: =UG2+1 -> 38 | UW2: 1 | UX2: 2 | UY2: 2 | UZ2: 3 | VA2: 4 | VB2: 5 | VC2: 6 | VD2: 7 | VE2: 8 | VF2: 9 | VG2: 10 | VH2: 11 | VI2: 12 | VJ2: 13 | VK2: 14 | VL2: 15 | VM2: 16 | VN2: 17 | VO2: 18 | VP2: 19 | VQ2: 20 | VR2: 21 | VS2: 22 | VT2: 23 | VU2: 24 | VV2: 25 | VW2: 26 | VX2: 27 | VY2: 28 | VZ2: 29 | WA2: 30 | WB2: 31 | WC2: 32 | WD2: 33 | WE2: 34 | WF2: 35 | WG2: 36 | WH2: 37 | WI2: =MAX(F4:F11) -> 20
D3: # | E3: Teams | F3: J | G3: G | H3: E | I3: P | J3: Ptos | K3: GF | L3: GC | M3: GF - GC | N3: GD | O3: CS-GF | P3: CS-GC | R3: J | S3: G | T3: E | U3: P | V3: Ptos | W3: GF | X3: GC | Y3: GF - GC | Z3: GD | AA3: CS-GF | AB3: CS-GC | AD3: J | AE3: G | AF3: E | AG3: P | AH3: Ptos | AI3: GF | AJ3: GC | AK3: GF - GC | AL3: GD | AM3: CS-GF | AN3: CS-GC | AV3: J | AW3: G | AX3: E | AY3: P | AZ3: Ptos | BA3: GF - GC | BB3: GD | BC3: J | BD3: G | BE3: E | BF3: P | BG3: Ptos | BH3: GF - GC | BI3: GD | BJ3: J | BK3: G | BL3: E | BM3: P | BN3: Ptos | BO3: GF - GC | BP3: GD | BS3: - 12:00 | BT3: 0.5 | BU3: =BT3-$BU$2 -> 0.33333333 | BV3: menos | CA3: Most Points | CB3: Fewest Points | CC3: Most Wins | CD3: Fewest Wins | CE3: Most Losses | CF3: Fewest Losses | CG3: Most Goal Scored | CH3: Fewest Goals Scored | CI3: Most Goals Conceded | CJ3: Fewest Goals Conceded | CK3: Highest Goal Difference | CL3: Lowest Goal Difference | CM3: Most Games Failed to Score | CN3: Fewest Games Failed to Score | CO3: Most Clean Sheets | CP3: Fewest Clean Sheets | CR3: Most Points | CS3: Fewest Points | CT3: Most Wins | CU3: Fewest Wins | CV3: Most Losses | CW3: Fewest Losses | CX3: Most Goal Scored | CY3: Fewest Goals Scored | CZ3: Most Goals Conceded | DA3: Fewest Goals Conceded | DB3: Highest Goal Difference | DC3: Lowest Goal Difference | DD3: Most Games Failed to Score | DE3: Fewest Games Failed to Score | DF3: Most Clean Sheets | DG3: Fewest Clean Sheets | DI3: Most Points | DJ3: Fewest Points | DK3: Most Wins | DL3: Fewest Wins | DM3: Most Losses | DN3: Fewest Losses | DO3: Most Goal Scored | DP3: Fewest Goals Scored | DQ3: Most Goals Conceded | DR3: Fewest Goals Conceded | DS3: Highest Goal Difference | DT3: Lowest Goal Difference | DU3: Most Games Failed to Score | DV3: Fewest Games Failed to Score | DW3: Most Clean Sheets | DX3: Fewest Clean Sheets | EB3: Most Points | EC3: Fewest Points | ED3: Most Wins | EE3: Fewest Wins | EF3: Most Losses | EG3: Fewest Losses | EH3: Most Goal Scored | EI3: Fewest Goals Scored | EJ3: Most Goals Conceded | EK3: Fewest Goals Conceded | EL3: Highest Goal Difference | EM3: Lowest Goal Difference | EN3: Most Games Failed to Score | EO3: Fewest Games Failed to Score | EP3: Most Clean Sheets | EQ3: Fewest Clean Sheets | ES3: Most Points | ET3: Fewest Points | EU3: Most Points | EV3: Fewest Points | EW3: Most Wins | EX3: Fewest Wins | EY3: Most Losses | EZ3: Fewest Losses | FA3: Most Goal Scored | FB3: Fewest Goals Scored | FC3: Highest Goal Difference | FD3: Lowest Goal Difference | FE3: Most Games Failed to Score | FF3: Fewest Games Failed to Score | FG3: Most Clean Sheets | FH3: Fewest Clean Sheets | FJ3: Most Points | FK3: Fewest Points | FL3: Most Wins | FM3: Fewest Wins | FN3: Most Losses | FO3: Fewest Losses | FP3: Most Goal Scored | FQ3: Fewest Goals Scored | FR3: Fewest Goals Conceded | FS3: Most Goals Conceded | FT3: Highest Goal Difference | FU3: Lowest Goal Difference | FV3: Most Games Failed to Score | FW3: Fewest Games Failed to Score | FX3: Most Clean Sheets | FY3: Fewest Clean Sheets | GA3: Most Points | GB3: Fewest Points | GC3: Most Wins | GD3: Fewest Wins | GE3: Most Losses | GF3: Fewest Losses | GG3: Most Goal Scored | GH3: Fewest Goals Scored | GI3: Fewest Goals Conceded | GJ3: Most Goals Conceded | GK3: Highest Goal Difference | GL3: Lowest Goal Difference | GM3: Most Games Failed to Score | GN3: Fewest Games Failed to Score | GO3: Most Clean Sheets | GP3: Fewest Clean Sheets | GR3: Most Points | GS3: Fewest Points | GT3: Most Wins | GU3: Fewest Wins | GV3: Most Losses | GW3: Fewest Losses | GX3: Most Goal Scored | GY3: Fewest Goals Scored | GZ3: Fewest Goals Conceded | HA3: Most Goals Conceded | HB3: Highest Goal Difference | HC3: Lowest Goal Difference | HD3: Most Games Failed to Score | HE3: Fewest Games Failed to Score | HF3: Most Clean Sheets | HG3: Fewest Clean Sheets | HJ3: J | HK3: G | HL3: E | HM3: P | HN3: Ptos | HO3: GF | HP3: GC | HQ3: GF - GC | HR3: GD | HS3: CS-GF | HT3: CS-GC | HV3: Most Points | HW3: Fewest Points | HX3: Most Wins | HY3: Fewest Wins | HZ3: Most Losses | IA3: Fewest Losses | IB3: Most Goal Scored | IC3: Fewest Goals Scored | ID3: Fewest Goals Conceded | IE3: Most Goals Conceded | IF3: Highest Goal Difference | IG3: Lowest Goal Difference | IH3: Most Games Failed to Score | II3: Fewest Games Failed to Score | IJ3: Most Clean Sheets | IK3: Fewest Clean Sheets | IO3: Type | IP3: No | IQ3: Total | IR3: % | IS3: Pos | IU3: Type | IV3: No | IW3: Total | IX3: % | IY3: Pos | JB3: Most Points | JC3: Fewest Points | JD3: Most Wins | JE3: Fewest Wins | JF3: Most Losses | JG3: Fewest Losses | JH3: Most Goal Scored | JI3: Fewest Goals Scored | JJ3: Fewest Goals Conceded | JK3: Most Goals Conceded | JL3: Highest Goal Difference | JM3: Lowest Goal Difference | JN3: Most Games Failed to Score | JO3: Fewest Games Failed to Score | JP3: Most Clean Sheets | JQ3: Fewest Clean Sheets | JS3: Most Points | JT3: Fewest Points | JU3: Most Wins | JV3: Fewest Wins | JW3: Most Losses | JX3: Fewest Losses | JY3: Most Goal Scored | JZ3: Fewest Goals Scored | KA3: Fewest Goals Conceded | KB3: Most Goals Conceded | KC3: Highest Goal Difference | KD3: Lowest Goal Difference | KE3: Most Games Failed to Score | KF3: Fewest Games Failed to Score | KG3: Most Clean Sheets | KH3: Fewest Clean Sheets | KM3: # | KN3: Teams | KO3: Ptos | KP3: GF | KQ3: GC | KU3: 1 | KV3: Ptos | KW3: GF | KX3: GC | LB3: =KU3+1 -> 2 | LC3: Ptos | LD3: GF | LE3: GC | LI3: =LB3+1 -> 3 | LJ3: Ptos | LK3: GF | LL3: GC | LP3: =LI3+1 -> 4 | LQ3: Ptos | LR3: GF | LS3: GC | LW3: =LP3+1 -> 5 | LX3: Ptos | LY3: GF | LZ3: GC | MD3: =LW3+1 -> 6 | ME3: Ptos | MF3: GF | MG3: GC | MK3: =MD3+1 -> 7 | ML3: Ptos | MM3: GF | MN3: GC | MR3: =MK3+1 -> 8 | MS3: Ptos | MT3: GF | MU3: GC | MY3: =MR3+1 -> 9 | MZ3: Ptos | NA3: GF | NB3: GC | NF3: =MY3+1 -> 10 | NG3: Ptos | NH3: GF | NI3: GC | NM3: =NF3+1 -> 11 | NN3: Ptos | NO3: GF | NP3: GC | NT3: =NM3+1 -> 12 | NU3: Ptos | NV3: GF | NW3: GC | OA3: =NT3+1 -> 13 | OB3: Ptos | OC3: GF | OD3: GC | OH3: =OA3+1 -> 14 | OI3: Ptos | OJ3: GF | OK3: GC | OO3: =OH3+1 -> 15 | OP3: Ptos | OQ3: GF | OR3: GC | OV3: =OO3+1 -> 16 | OW3: Ptos | OX3: GF | OY3: GC | PC3: =OV3+1 -> 17 | PD3: Ptos | PE3: GF | PF3: GC | PJ3: =PC3+1 -> 18 | PK3: Ptos | PL3: GF | PM3: GC | PQ3: =PJ3+1 -> 19 | PR3: Ptos | PS3: GF | PT3: GC | PX3: =PQ3+1 -> 20 | PY3: Ptos | PZ3: GF | QA3: GC | QE3: =PX3+1 -> 21 | QF3: Ptos | QG3: GF | QH3: GC | QL3: =QE3+1 -> 22 | QM3: Ptos | QN3: GF | QO3: GC | QS3: =QL3+1 -> 23 | QT3: Ptos | QU3: GF | QV3: GC | QZ3: =QS3+1 -> 24 | RA3: Ptos | RB3: GF | RC3: GC | RG3: =QZ3+1 -> 25 | RH3: Ptos | RI3: GF | RJ3: GC | RN3: =RG3+1 -> 26 | RO3: Ptos | RP3: GF | RQ3: GC | RU3: =RN3+1 -> 27 | RV3: Ptos | RW3: GF | RX3: GC | SB3: =RU3+1 -> 28 | SC3: Ptos | SD3: GF | SE3: GC | SI3: =SB3+1 -> 29 | SJ3: Ptos | SK3: GF | SL3: GC | SP3: =SI3+1 -> 30 | SQ3: Ptos | SR3: GF | SS3: GC | SW3: =SP3+1 -> 31 | SX3: Ptos | SY3: GF | SZ3: GC | TD3: =SW3+1 -> 32 | TE3: Ptos | TF3: GF | TG3: GC | TK3: =TD3+1 -> 33 | TL3: Ptos | TM3: GF | TN3: GC | TR3: =TK3+1 -> 34 | TS3: Ptos | TT3: GF | TU3: GC | TY3: =TR3+1 -> 35 | TZ3: Ptos | UA3: GF | UB3: GC | UF3: =TY3+1 -> 36 | UG3: Ptos | UH3: GF | UI3: GC | UM3: =UF3+1 -> 37 | UN3: Ptos | UO3: GF | UP3: GC | UT3: =UM3+1 -> 38 | UX3: 7 | UY3: =UX3+$UX3 -> 14 | UZ3: =UY3+$UX3 -> 21 | VA3: =UZ3+$UX3 -> 28 | VB3: =VA3+$UX3 -> 35 | VC3: =VB3+$UX3 -> 42 | VD3: =VC3+$UX3 -> 49 | VE3: =VD3+$UX3 -> 56 | VF3: =VE3+$UX3 -> 63 | ... WH3: =WG3+$UX3 -> 259 | WI3: =MAX(F12:F19) -> 21 | WN3: 1 | WO3: 2 | WP3: 3 | WQ3: 4 | WR3: 5 | WS3: 6 | WT3: 7 | WU3: 8 | WV3: 9 | WW3: 10 | WX3: 11 | WY3: 12 | WZ3: 13 | XA3: 14 | XB3: 15 | XC3: 16 | XD3: 17 | XE3: 18 | XF3: 19 | XG3: 20 | XH3: 21 | XI3: 22 | XJ3: 23 | XK3: 24 | XL3: 25 | XM3: 26 | XN3: 27 | XO3: 28 | XP3: 29 | XQ3: 30 | XR3: 31 | XS3: 32 | XT3: 33 | XU3: 34 | XV3: 35 | XW3: 36 | XX3: 37 | XY3: 38 | YE3: -1 | YF3: 0 | YG3: 1 | YH3: 2 | YI3: 3 | YJ3: 4 | YK3: 5 | YL3: 6 | YM3: 7 | YN3: 8 | YO3: 9 | YP3: 10 | YQ3: 11 | YR3: 12 | YS3: 13 | YT3: 14 | YU3: 15 | YV3: 16 | YW3: 17 | YX3: 18 | YY3: 19 | YZ3: 20 | ZA3: 21 | ZB3: 22 | ZC3: 23 | ZD3: 24 | ZE3: 25 | ZF3: 26 | ZG3: 27 | ZH3: 28 | ZI3: 29 | ZJ3: 30 | ZK3: 31 | ZL3: 32 | ZM3: 33 | ZN3: 34 | ZO3: 35 | ZP3: 36 | ZQ3: 37 | ZR3: 38
